Workbook

Sheet TreatmentInputDB before changes
A1: <Intervention Master ID> | B1: <Intervention Name> | C1: <Special Case Type Master IDs> | D1: <Delivery Channel Master IDs> | E1: <Treatment Input Type Master ID> | F1: <Group Master ID> | G1: <Group Name> | H1: <Group String Constant> | I1: <Input Master ID> | J1: <Input Name> | K1: <Percent Receiving or Percent Treated By> | L1: <Note> | M1: <Note String Constant> | N1: <Number of Items> | O1: <Times per Day or Minutes> | P1: <Days per Case or Number of Days> | Q1: <Units per Case or Units per Person>
A2: 1 | B2: Syphilis detection and treatment (pregnant women) | C2: 1 | D2: 4, 6 | E2: 1 | F2: 1 | G2: Screening | H2: GB_stNull | I2: 17 | J2: Blood collecting tube, 5 ml | K2: 100 | L2: For taking blood sample | M2: GB_stNull | N2: 1 | O2: 1 | P2: 1 | Q2: 1
A3: 1 | B3: Syphilis detection and treatment (pregnant women) | C3: 1 | D3: 4, 6 | E3: 1 | F3: 1 | G3: Screening | H3: GB_stNull | I3: 58 | J3: Gloves, exam, latex, disposable, pair | K3: 100 | M3: GB_stNull | N3: 1 | O3: 1 | P3: 1 | Q3: 1
A4: 1 | B4: Syphilis detection and treatment (pregnant women) | C4: 1 | D4: 4, 6 | E4: 1 | F4: 1 | G4: Screening | H4: GB_stNull | I4: 144 | J4: Syringe, needle + swab | K4: 100 | L4: For taking blood sample | M4: GB_stNull | N4: 1 | O4: 1 | P4: 1 | Q4: 1
A5: 1 | B5: Syphilis detection and treatment (pregnant women) | C5: 1 | D5: 4, 6 | E5: 1 | F5: 1 | G5: Screening | H5: GB_stNull | I5: 234 | J5: Test, Rapid plasma reagin (RPR) | K5: 100 | L5: Syphilis test | M5: GB_stNull | N5: 1 | O5: 1 | P5: 1 | Q5: 1
A6: 1 | B6: Syphilis detection and treatment (pregnant women) | C6: 1 | D6: 4, 6 | E6: 1 | F6: 2 | G6: Treatment | H6: GB_stNull | I6: 15 | J6: Benzathine benzylpenicillin, powder for injection, 2.4 million IU | K6: 0.885 | L6: Antibiotic | M6: GB_stNull | N6: 1 | O6: 1 | P6: 1 | Q6: 1
A7: 1 | B7: Syphilis detection and treatment (pregnant women) | C7: 1 | D7: 4, 6 | E7: 1 | F7: 2 | G7: Treatment | H7: GB_stNull | I7: 144 | J7: Syringe, needle + swab | K7: 0.885 | L7: for benzathine benzylpenicillin injection | M7: GB_stNull | N7: 1 | O7: 1 | P7: 1 | Q7: 1
A8: 1 | B8: Syphilis detection and treatment (pregnant women) | C8: 1 | D8: 4, 6 | E8: 1 | F8: 2 | G8: Treatment | H8: GB_stNull | I8: 163 | J8: Water for injection, 5 ml ampoule | K8: 0.885 | L8: for benzathine benzylpenicillin injection | M8: GB_stNull | N8: 1 | O8: 1 | P8: 1 | Q8: 1
A9: 1 | B9: Syphilis detection and treatment (pregnant women) | C9: 1 | D9: 4, 6 | E9: 2 | F9: 1 | G9: Screening | H9: GB_stNull | I9: 7 | J9: Midwifery professionals | K9: 100 | M9: GB_stNull | O9: 15 | P9: 1 | Q9: 15
A10: 1 | B10: Syphilis detection and treatment (pregnant women) | C10: 1 | D10: 4, 6 | E10: 2 | F10: 2 | G10: Injection | H10: GB_stNull | I10: 7 | J10: Midwifery professionals | K10: 20 | M10: GB_stNull | O10: 5 | P10: 1 | Q10: 5
A11: 1 | B11: Syphilis detection and treatment (pregnant women) | C11: 1 | D11: 4, 6 | E11: 2 | F11: 3 | G11: Follow-up | H11: GB_stNull | I11: 7 | J11: Midwifery professionals | K11: 20 | M11: GB_stNull | O11: 5 | P11: 1 | Q11: 5
A12: 1 | B12: Syphilis detection and treatment (pregnant women) | C12: 1 | D12: 4, 6 | E12: 9 | F12: 0 | H12: GB_stNull | I12: 1 | J12: Outpatient visit | K12: 100 | L12: Part of ANC visit | M12: GB_stNull | Q12: 0
A13: 1 | B13: Syphilis detection and treatment (pregnant women) | C13: 1 | D13: 4, 6 | E13: 9 | F13: 0 | H13: GB_stNull | I13: 2 | J13: Inpatient days | K13: 100 | M13: GB_stNull | Q13: 0
A14: 3 | B14: IPT (pregnant women) | C14: 1 | D14: 4, 6 | E14: 1 | F14: 0 | H14: GB_stNull | I14: 134 | J14: Sulfamethoxazole + trimethropin, tablet 400 mg + 80 mg | K14: 100 | L14: Intermittent preventive treatment (IPT) at least 2x during 2nd and 3rd trimester | M14: GB_stNull | N14: 1 | O14: 1 | P14: 6 | Q14: 6
A15: 3 | B15: IPT (pregnant women) | C15: 1 | D15: 4, 6 | E15: 2 | F15: 0 | H15: GB_stNull | I15: 8 | J15: Midwifery associate professionals | K15: 100 | M15: GB_stNull | O15: 2.5 | P15: 2 | Q15: 5
A16: 3 | B16: IPT (pregnant women) | C16: 1 | D16: 1 | E16: 2 | F16: 0 | H16: GB_stNull | I16: 14 | J16: Community health workers | K16: 100 | M16: GB_stNull | O16: 2.5 | P16: 2 | Q16: 5
A17: 3 | B17: IPT (pregnant women) | C17: 1 | D17: 6 | E17: 9 | F17: 0 | H17: GB_stNull | I17: 1 | J17: Outpatient visit | K17: 100 | M17: GB_stNull | Q17: 2
A18: 3 | B18: IPT (pregnant women) | C18: 1 | D18: 6 | E18: 9 | F18: 0 | H18: GB_stNull | I18: 2 | J18: Inpatient day | K18: 100 | M18: GB_stNull | Q18: 0
A19: 4 | B19: Tetanus toxoid (pregnant women) | C19: 1 | D19: 2, 4, 6 | E19: 1 | F19: 0 | H19: GB_stNull | I19: 152 | J19: Tetanus toxoid, injection | K19: 100 | M19: GB_stNull | N19: 1 | O19: 1 | P19: 2 | Q19: 2
A20: 4 | B20: Tetanus toxoid (pregnant women) | C20: 1 | D20: 2, 4, 6 | E20: 1 | F20: 0 | H20: GB_stNull | I20: 144 | J20: Syringe, needle + swab | K20: 100 | M20: GB_stNull | N20: 1 | O20: 1 | P20: 2 | Q20: 2
A21: 4 | B21: Tetanus toxoid (pregnant women) | C21: 1 | D21: 2 | E21: 2 | F21: 0 | H21: GB_stNull | I21: 7 | J21: Midwifery professionals | K21: 100 | M21: GB_stNull | O21: 7.5 | P21: 2 | Q21: 15
A22: 4 | B22: Tetanus toxoid (pregnant women) | C22: 1 | D22: 4, 6 | E22: 2 | F22: 0 | H22: GB_stNull | I22: 7 | J22: Midwifery professionals | K22: 100 | M22: GB_stNull | O22: 2.5 | P22: 2 | Q22: 5
A23: 4 | B23: Tetanus toxoid (pregnant women) | C23: 1 | D23: 2, 4, 6 | E23: 9 | F23: 0 | H23: GB_stNull | I23: 1 | J23: Outpatient visit | K23: 100 | M23: GB_stNull | Q23: 2
A24: 4 | B24: Tetanus toxoid (pregnant women) | C24: 1 | D24: 4 | E24: 9 | F24: 0 | H24: GB_stNull | I24: 2 | J24: Inpatient days | K24: 100 | M24: GB_stNull | Q24: 0
A25: 5 | B25: Antenatal corticosteroids for preterm labor | D25: 4 | E25: 1 | F25: 0 | H25: GB_stNull | I25: 36 | J25: Dexamethasone, 1 ml injection, 4 mg/ml | K25: 100 | L25: Intramuscular injection | M25: GB_stNull | N25: 1.5 | O25: 2 | P25: 2 | Q25: 6
A26: 5 | B26: Antenatal corticosteroids for preterm labor | D26: 4 | E26: 1 | F26: 0 | H26: GB_stNull | I26: 144 | J26: Syringe, needle + swab | K26: 100 | L26: For dexamethasone | M26: GB_stNull | N26: 1 | O26: 1 | P26: 2 | Q26: 2
A27: 5 | B27: Antenatal corticosteroids for preterm labor | D27: 4 | E27: 1 | F27: 0 | H27: GB_stNull | I27: 321 | J27: Nifedipine | K27: 100 | M27: GB_stNull | N27: 1 | O27: 2 | P27: 2 | Q27: 4
A28: 5 | B28: Antenatal corticosteroids for preterm labor | D28: 4 | E28: 2 | F28: 0 | H28: GB_stNull | I28: 4 | J28: Specialist medical practitioners | K28: 100 | L28: To confirm diagnosis and prescribe treatment | M28: GB_stNull | O28: 30 | P28: 1 | Q28: 30
A29: 5 | B29: Antenatal corticosteroids for preterm labor | D29: 4 | E29: 2 | F29: 0 | H29: GB_stNull | I29: 7 | J29: Midwifery professionals | K29: 100 | M29: GB_stNull | O29: 20 | P29: 2 | Q29: 40
A30: 5 | B30: Antenatal corticosteroids for preterm labor | D30: 4 | E30: 9 | F30: 0 | H30: GB_stNull | I30: 1 | J30: Outpatient visits | K30: 100 | M30: GB_stNull | Q30: 0
A31: 5 | B31: Antenatal corticosteroids for preterm labor | D31: 4 | E31: 9 | F31: 0 | H31: GB_stNull | I31: 2 | J31: Inpatient days | K31: 100 | M31: GB_stNull | Q31: 2
A32: 6 | B32: Antibiotics for preterm or prolonged PROM | C32: 1 | D32: 4, 6 | E32: 1 | F32: 0 | H32: GB_stNull | I32: 43 | J32: Erythromycin, tablet, 250 mg | K32: 100 | M32: GB_stNull | N32: 1 | O32: 4 | P32: 10 | Q32: 40
A33: 6 | B33: Antibiotics for preterm or prolonged PROM | C33: 1 | D33: 1, 2, 4, 6 | E33: 2 | F33: 0 | H33: GB_stNull | I33: 7 | J33: Midwifery professionals | K33: 100 | M33: GB_stNull | O33: 15 | P33: 2 | Q33: 30
A34: 6 | B34: Antibiotics for preterm or prolonged PROM | C34: 1 | D34: 1, 2, 4, 6 | E34: 9 | F34: 0 | H34: GB_stNull | I34: 1 | J34: Outpatient visit | K34: 50 | M34: GB_stNull | Q34: 0
A35: 6 | B35: Antibiotics for preterm or prolonged PROM | C35: 1 | D35: 1, 2, 4, 6 | E35: 9 | F35: 0 | H35: GB_stNull | I35: 2 | J35: Inpatient days | K35: 50 | M35: GB_stNull | Q35: 2
A36: 7 | B36: Intermittent iron-folic acid supplementation (menstruating women where anaemia is public health problem) | C36: 1 | D36: 1 | E36: 1 | F36: 0 | H36: GB_stNull | I36: 287 | J36: Folic acid fortification drugs/supplies to service a client | K36: 100 | L36: Folic acid fortification supplies for maize or wheat flour per person per year | M36: GB_stNull | N36: 1 | O36: 1 | P36: 1 | Q36: 1
A37: 8 | B37: Nutritional care and support for pregnant and lactating women in emergencies | C37: 1 | D37: 2, 4, 6 | E37: 1 | F37: 0 | H37: GB_stNull | I37: 974 | J37: High energy biscuit, 100 grams | K37: 100 | M37: GB_stNull | N37: 1 | O37: 3 | P37: 180 | Q37: 540
A38: 8 | B38: Nutritional care and support for pregnant and lactating women in emergencies | C38: 1 | D38: 2, 4, 6 | E38: 2 | F38: 0 | H38: GB_stNull | I38: 7 | J38: Midwifery professionals | K38: 100 | L38: Included as part of ANC | M38: GB_stNull | O38: 2 | P38: 4 | Q38: 8
A39: 9 | B39: Multiple micronutrient supplementation in pregnancy | C39: 1 | D39: 1, 2, 4, 6 | E39: 1 | F39: 0 | H39: GB_stNull | I39: 91 | J39: Micronutrient, film-coated tablet | K39: 100 | L39: 100% of pregnant women for 6 months of pregnancy | M39: GB_stNull | N39: 1 | O39: 1 | P39: 180 | Q39: 180
A40: 9 | B40: Multiple micronutrient supplementation in pregnancy | C40: 1 | D40: 1, 2, 4, 6 | E40: 2 | F40: 0 | H40: GB_stNull | I40: 7 | J40: Midwifery professionals | K40: 100 | L40: Added to ANC or infant checkups | M40: GB_stNull | O40: 2 | P40: 4 | Q40: 8
...

Sheet TreatmentInputDB
A1: <Intervention Master ID> | B1: <Intervention Name> | C1: <Special Case Type Master IDs> | D1: <Delivery Channel Master IDs> | E1: <Treatment Input Type Master ID> | F1: <Group Master ID> | G1: <Group Name> | H1: <Group String Constant> | I1: <Input Master ID> | J1: <Input Name> | K1: <Percent Receiving or Percent Treated By> | L1: <Note> | M1: <Note String Constant> | N1: <Number of Items> | O1: <Times per Day or Minutes> | P1: <Days per Case or Number of Days> | Q1: <Units per Case or Units per Person>
A2: 1 | B2: Syphilis detection and treatment (pregnant women) | C2: 1 | D2: 4, 6 | E2: 1 | F2: 1 | G2: Screening | H2: GB_stNull | I2: 17 | J2: Blood collecting tube, 5 ml | K2: 100 | L2: For taking blood sample | M2: GB_stNull | N2: 1 | O2: 1 | P2: 1 | Q2: 1 | S2: =IF(E2=1, I2, "") -> 17
A3: 1 | B3: Syphilis detection and treatment (pregnant women) | C3: 1 | D3: 4, 6 | E3: 1 | F3: 1 | G3: Screening | H3: GB_stNull | I3: 58 | J3: Gloves, exam, latex, disposable, pair | K3: 100 | M3: GB_stNull | N3: 1 | O3: 1 | P3: 1 | Q3: 1 | S3: =IF(E3=1, I3, "") -> 58
A4: 1 | B4: Syphilis detection and treatment (pregnant women) | C4: 1 | D4: 4, 6 | E4: 1 | F4: 1 | G4: Screening | H4: GB_stNull | I4: 144 | J4: Syringe, needle + swab | K4: 100 | L4: For taking blood sample | M4: GB_stNull | N4: 1 | O4: 1 | P4: 1 | Q4: 1 | S4: =IF(E4=1, I4, "") -> 144
A5: 1 | B5: Syphilis detection and treatment (pregnant women) | C5: 1 | D5: 4, 6 | E5: 1 | F5: 1 | G5: Screening | H5: GB_stNull | I5: 234 | J5: Test, Rapid plasma reagin (RPR) | K5: 100 | L5: Syphilis test | M5: GB_stNull | N5: 1 | O5: 1 | P5: 1 | Q5: 1 | S5: =IF(E5=1, I5, "") -> 234
A6: 1 | B6: Syphilis detection and treatment (pregnant women) | C6: 1 | D6: 4, 6 | E6: 1 | F6: 2 | G6: Treatment | H6: GB_stNull | I6: 15 | J6: Benzathine benzylpenicillin, powder for injection, 2.4 million IU | K6: 0.885 | L6: Antibiotic | M6: GB_stNull | N6: 1 | O6: 1 | P6: 1 | Q6: 1 | S6: =IF(E6=1, I6, "") -> 15
A7: 1 | B7: Syphilis detection and treatment (pregnant women) | C7: 1 | D7: 4, 6 | E7: 1 | F7: 2 | G7: Treatment | H7: GB_stNull | I7: 144 | J7: Syringe, needle + swab | K7: 0.885 | L7: for benzathine benzylpenicillin injection | M7: GB_stNull | N7: 1 | O7: 1 | P7: 1 | Q7: 1 | S7: =IF(E7=1, I7, "") -> 144
A8: 1 | B8: Syphilis detection and treatment (pregnant women) | C8: 1 | D8: 4, 6 | E8: 1 | F8: 2 | G8: Treatment | H8: GB_stNull | I8: 163 | J8: Water for injection, 5 ml ampoule | K8: 0.885 | L8: for benzathine benzylpenicillin injection | M8: GB_stNull | N8: 1 | O8: 1 | P8: 1 | Q8: 1 | S8: =IF(E8=1, I8, "") -> 163
A9: 1 | B9: Syphilis detection and treatment (pregnant women) | C9: 1 | D9: 4, 6 | E9: 2 | F9: 1 | G9: Screening | H9: GB_stNull | I9: 7 | J9: Midwifery professionals | K9: 100 | M9: GB_stNull | O9: 15 | P9: 1 | Q9: 15 | S9: =IF(E9=1, I9, "")
A10: 1 | B10: Syphilis detection and treatment (pregnant women) | C10: 1 | D10: 4, 6 | E10: 2 | F10: 2 | G10: Injection | H10: GB_stNull | I10: 7 | J10: Midwifery professionals | K10: 20 | M10: GB_stNull | O10: 5 | P10: 1 | Q10: 5 | S10: =IF(E10=1, I10, "")
A11: 1 | B11: Syphilis detection and treatment (pregnant women) | C11: 1 | D11: 4, 6 | E11: 2 | F11: 3 | G11: Follow-up | H11: GB_stFollowUp | I11: 7 | J11: Midwifery professionals | K11: 20 | M11: GB_stNull | O11: 5 | P11: 1 | Q11: 5 | S11: =IF(E11=1, I11, "")
A12: 1 | B12: Syphilis detection and treatment (pregnant women) | C12: 1 | D12: 4, 6 | E12: 9 | F12: 0 | H12: GB_stNull | I12: 1 | J12: Outpatient visit | K12: 100 | L12: Part of ANC visit | M12: GB_stNull | Q12: 0 | S12: =IF(E12=1, I12, "")
A13: 1 | B13: Syphilis detection and treatment (pregnant women) | C13: 1 | D13: 4, 6 | E13: 9 | F13: 0 | H13: GB_stNull | I13: 2 | J13: Inpatient days | K13: 100 | M13: GB_stNull | Q13: 0 | S13: =IF(E13=1, I13, "")
A14: 3 | B14: IPT (pregnant women) | C14: 1 | D14: 4, 6 | E14: 1 | F14: 0 | H14: GB_stNull | I14: 134 | J14: Sulfamethoxazole + trimethropin, tablet 400 mg + 80 mg | K14: 100 | L14: Intermittent preventive treatment (IPT) at least 2x during 2nd and 3rd trimester | M14: GB_stNull | N14: 1 | O14: 1 | P14: 6 | Q14: 6 | S14: =IF(E14=1, I14, "") -> 134
A15: 3 | B15: IPT (pregnant women) | C15: 1 | D15: 4, 6 | E15: 2 | F15: 0 | H15: GB_stNull | I15: 8 | J15: Midwifery associate professionals | K15: 100 | M15: GB_stNull | O15: 2.5 | P15: 2 | Q15: 5 | S15: =IF(E15=1, I15, "")
A16: 3 | B16: IPT (pregnant women) | C16: 1 | D16: 1 | E16: 2 | F16: 0 | H16: GB_stNull | I16: 14 | J16: Community health workers | K16: 100 | M16: GB_stNull | O16: 2.5 | P16: 2 | Q16: 5 | S16: =IF(E16=1, I16, "")
A17: 3 | B17: IPT (pregnant women) | C17: 1 | D17: 6 | E17: 9 | F17: 0 | H17: GB_stNull | I17: 1 | J17: Outpatient visit | K17: 100 | M17: GB_stNull | Q17: 2 | S17: =IF(E17=1, I17, "")
A18: 3 | B18: IPT (pregnant women) | C18: 1 | D18: 6 | E18: 9 | F18: 0 | H18: GB_stNull | I18: 2 | J18: Inpatient day | K18: 100 | M18: GB_stNull | Q18: 0 | S18: =IF(E18=1, I18, "")
A19: 4 | B19: Tetanus toxoid (pregnant women) | C19: 1 | D19: 2, 4, 6 | E19: 1 | F19: 0 | H19: GB_stNull | I19: 152 | J19: Tetanus toxoid, injection | K19: 100 | M19: GB_stNull | N19: 1 | O19: 1 | P19: 2 | Q19: 2 | S19: =IF(E19=1, I19, "") -> 152
A20: 4 | B20: Tetanus toxoid (pregnant women) | C20: 1 | D20: 2, 4, 6 | E20: 1 | F20: 0 | H20: GB_stNull | I20: 144 | J20: Syringe, needle + swab | K20: 100 | M20: GB_stNull | N20: 1 | O20: 1 | P20: 2 | Q20: 2 | S20: =IF(E20=1, I20, "") -> 144
A21: 4 | B21: Tetanus toxoid (pregnant women) | C21: 1 | D21: 2 | E21: 2 | F21: 0 | H21: GB_stNull | I21: 7 | J21: Midwifery professionals | K21: 100 | M21: GB_stNull | O21: 7.5 | P21: 2 | Q21: 15 | S21: =IF(E21=1, I21, "")
A22: 4 | B22: Tetanus toxoid (pregnant women) | C22: 1 | D22: 4, 6 | E22: 2 | F22: 0 | H22: GB_stNull | I22: 7 | J22: Midwifery professionals | K22: 100 | M22: GB_stNull | O22: 2.5 | P22: 2 | Q22: 5 | S22: =IF(E22=1, I22, "")
A23: 4 | B23: Tetanus toxoid (pregnant women) | C23: 1 | D23: 2, 4, 6 | E23: 9 | F23: 0 | H23: GB_stNull | I23: 1 | J23: Outpatient visit | K23: 100 | M23: GB_stNull | Q23: 2 | S23: =IF(E23=1, I23, "")
A24: 4 | B24: Tetanus toxoid (pregnant women) | C24: 1 | D24: 4 | E24: 9 | F24: 0 | H24: GB_stNull | I24: 2 | J24: Inpatient days | K24: 100 | M24: GB_stNull | Q24: 0 | S24: =IF(E24=1, I24, "")
A25: 5 | B25: Antenatal corticosteroids for preterm labor | D25: 4 | E25: 1 | F25: 0 | H25: GB_stNull | I25: 36 | J25: Dexamethasone, 1 ml injection, 4 mg/ml | K25: 100 | L25: Intramuscular injection | M25: GB_stNull | N25: 1.5 | O25: 2 | P25: 2 | Q25: 6 | S25: =IF(E25=1, I25, "") -> 36
A26: 5 | B26: Antenatal corticosteroids for preterm labor | D26: 4 | E26: 1 | F26: 0 | H26: GB_stNull | I26: 144 | J26: Syringe, needle + swab | K26: 100 | L26: For dexamethasone | M26: GB_stNull | N26: 1 | O26: 1 | P26: 2 | Q26: 2 | S26: =IF(E26=1, I26, "") -> 144
A27: 5 | B27: Antenatal corticosteroids for preterm labor | D27: 4 | E27: 1 | F27: 0 | H27: GB_stNull | I27: 321 | J27: Nifedipine | K27: 100 | M27: GB_stNull | N27: 1 | O27: 2 | P27: 2 | Q27: 4 | S27: =IF(E27=1, I27, "") -> 321
A28: 5 | B28: Antenatal corticosteroids for preterm labor | D28: 4 | E28: 2 | F28: 0 | H28: GB_stNull | I28: 4 | J28: Specialist medical practitioners | K28: 100 | L28: To confirm diagnosis and prescribe treatment | M28: GB_stNull | O28: 30 | P28: 1 | Q28: 30 | S28: =IF(E28=1, I28, "")
A29: 5 | B29: Antenatal corticosteroids for preterm labor | D29: 4 | E29: 2 | F29: 0 | H29: GB_stNull | I29: 7 | J29: Midwifery professionals | K29: 100 | M29: GB_stNull | O29: 20 | P29: 2 | Q29: 40 | S29: =IF(E29=1, I29, "")
A30: 5 | B30: Antenatal corticosteroids for preterm labor | D30: 4 | E30: 9 | F30: 0 | H30: GB_stNull | I30: 1 | J30: Outpatient visits | K30: 100 | M30: GB_stNull | Q30: 0 | S30: =IF(E30=1, I30, "")
A31: 5 | B31: Antenatal corticosteroids for preterm labor | D31: 4 | E31: 9 | F31: 0 | H31: GB_stNull | I31: 2 | J31: Inpatient days | K31: 100 | M31: GB_stNull | Q31: 2 | S31: =IF(E31=1, I31, "")
A32: 6 | B32: Antibiotics for preterm or prolonged PROM | C32: 1 | D32: 4, 6 | E32: 1 | F32: 0 | H32: GB_stNull | I32: 43 | J32: Erythromycin, tablet, 250 mg | K32: 100 | M32: GB_stNull | N32: 1 | O32: 4 | P32: 10 | Q32: 40 | S32: =IF(E32=1, I32, "") -> 43
A33: 6 | B33: Antibiotics for preterm or prolonged PROM | C33: 1 | D33: 1, 2, 4, 6 | E33: 2 | F33: 0 | H33: GB_stNull | I33: 7 | J33: Midwifery professionals | K33: 100 | M33: GB_stNull | O33: 15 | P33: 2 | Q33: 30 | S33: =IF(E33=1, I33, "")
A34: 6 | B34: Antibiotics for preterm or prolonged PROM | C34: 1 | D34: 1, 2, 4, 6 | E34: 9 | F34: 0 | H34: GB_stNull | I34: 1 | J34: Outpatient visit | K34: 50 | M34: GB_stNull | Q34: 0 | S34: =IF(E34=1, I34, "")
A35: 6 | B35: Antibiotics for preterm or prolonged PROM | C35: 1 | D35: 1, 2, 4, 6 | E35: 9 | F35: 0 | H35: GB_stNull | I35: 2 | J35: Inpatient days | K35: 50 | M35: GB_stNull | Q35: 2 | S35: =IF(E35=1, I35, "")
A36: 7 | B36: Intermittent iron-folic acid supplementation (menstruating women where anaemia is public health problem) | C36: 1 | D36: 1 | E36: 1 | F36: 0 | H36: GB_stNull | I36: 287 | J36: Folic acid fortification drugs/supplies to service a client | K36: 100 | L36: Folic acid fortification supplies for maize or wheat flour per person per year | M36: GB_stNull | N36: 1 | O36: 1 | P36: 1 | Q36: 1 | S36: =IF(E36=1, I36, "") -> 287
A37: 8 | B37: Nutritional care and support for pregnant and lactating women in emergencies | C37: 1 | D37: 2, 4, 6 | E37: 1 | F37: 0 | H37: GB_stNull | I37: 974 | J37: High energy biscuit, 100 grams | K37: 100 | M37: GB_stNull | N37: 1 | O37: 3 | P37: 180 | Q37: 540 | S37: =IF(E37=1, I37, "") -> 974
A38: 8 | B38: Nutritional care and support for pregnant and lactating women in emergencies | C38: 1 | D38: 2, 4, 6 | E38: 2 | F38: 0 | H38: GB_stNull | I38: 7 | J38: Midwifery professionals | K38: 100 | L38: Included as part of ANC | M38: GB_stNull | O38: 2 | P38: 4 | Q38: 8 | S38: =IF(E38=1, I38, "")
A39: 9 | B39: Multiple micronutrient supplementation in pregnancy | C39: 1 | D39: 1, 2, 4, 6 | E39: 1 | F39: 0 | H39: GB_stNull | I39: 91 | J39: Micronutrient, film-coated tablet | K39: 100 | L39: 100% of pregnant women for 6 months of pregnancy | M39: GB_stNull | N39: 1 | O39: 1 | P39: 180 | Q39: 180 | S39: =IF(E39=1, I39, "") -> 91
A40: 9 | B40: Multiple micronutrient supplementation in pregnancy | C40: 1 | D40: 1, 2, 4, 6 | E40: 2 | F40: 0 | H40: GB_stNull | I40: 7 | J40: Midwifery professionals | K40: 100 | L40: Added to ANC or infant checkups | M40: GB_stNull | O40: 2 | P40: 4 | Q40: 8 | S40: =IF(E40=1, I40, "")
...

Sheet Removed Treatment Inputs
A1: <Intervention Master ID> | B1: <Intervention Name> | C1: <Special Case Type Master IDs> | D1: <Delivery Channel Master IDs> | E1: <Treatment Input Type Master ID> | F1: <Group Master ID> | G1: <Group Name> | H1: <Group String Constant> | I1: <Input Master ID> | J1: <Input Name> | K1: <Percent Receiving or Percent Treated By> | L1: <Note> | M1: <Note String Constant> | N1: <Number of Items> | O1: <Times per Day or Minutes> | P1: <Days per Case or Number of Days> | Q1: <Units per Case or Units per Person>
A2: 646 | B2: Syphilis detection | C2: 1 | D2: 4, 6 | E2: 1 | F2: 0 | H2: GB_stNull | I2: 17 | J2: Blood collecting tube, 5 ml | K2: 100 | L2: For taking blood sample | M2: GB_stNull | N2: 1 | O2: 1 | P2: 1 | Q2: 1
A3: 646 | B3: Syphilis detection | C3: 1 | D3: 4, 6 | E3: 1 | F3: 0 | H3: GB_stNull | I3: 58 | J3: Gloves, exam, latex, disposable, pair | K3: 100 | M3: GB_stNull | N3: 1 | O3: 1 | P3: 1 | Q3: 1
A4: 646 | B4: Syphilis detection | C4: 1 | D4: 4, 6 | E4: 1 | F4: 0 | H4: GB_stNull | I4: 144 | J4: Syringe, needle + swab | K4: 100 | L4: For taking blood sample | M4: GB_stNull | N4: 1 | O4: 1 | P4: 1 | Q4: 1
A5: 646 | B5: Syphilis detection | C5: 1 | D5: 4, 6 | E5: 1 | F5: 0 | H5: GB_stNull | I5: 234 | J5: Test, Rapid plasma reagin (RPR) | K5: 100 | L5: Syphilis test | M5: GB_stNull | N5: 1 | O5: 1 | P5: 1 | Q5: 1
A6: 646 | B6: Syphilis detection | C6: 1 | D6: 4, 6 | E6: 2 | F6: 0 | H6: GB_stNull | I6: 7 | J6: Midwifery professionals | K6: 100 | M6: GB_stNull | O6: 15 | P6: 1 | Q6: 15
A7: 646 | B7: Syphilis detection | C7: 1 | D7: 4, 6 | E7: 9 | F7: 0 | H7: GB_stNull | I7: 1 | J7: Outpatient visit | K7: 100 | L7: Part of ANC visit | M7: GB_stNull | Q7: 0
A8: 646 | B8: Syphilis detection | C8: 1 | D8: 4, 6 | E8: 9 | F8: 0 | H8: GB_stNull | I8: 2 | J8: Inpatient day | K8: 100 | M8: GB_stNull | Q8: 0
A9: 647 | B9: Syphilis treatment | C9: 1 | D9: 4, 6 | E9: 1 | F9: 0 | H9: GB_stNull | I9: 15 | J9: Benzathine benzylpenicillin, powder for injection, 2.4 million IU | K9: 100 | L9: Antibiotic | M9: GB_stNull | N9: 1 | O9: 1 | P9: 1 | Q9: 1
A10: 647 | B10: Syphilis treatment | C10: 1 | D10: 4, 6 | E10: 1 | F10: 0 | H10: GB_stNull | I10: 144 | J10: Syringe, needle + swab | K10: 100 | L10: for benzathine benzylpenicillin injection | M10: GB_stNull | N10: 1 | O10: 1 | P10: 1 | Q10: 1
A11: 647 | B11: Syphilis treatment | C11: 1 | D11: 4, 6 | E11: 1 | F11: 0 | H11: GB_stNull | I11: 163 | J11: Water for injection, 5 ml ampoule | K11: 100 | L11: for benzathine benzylpenicillin injection | M11: GB_stNull | N11: 1 | O11: 1 | P11: 1 | Q11: 1
A12: 647 | B12: Syphilis treatment | C12: 1 | D12: 4, 6 | E12: 2 | F12: 1 | G12: Injection | H12: GB_stNull | I12: 7 | J12: Midwifery professionals | K12: 100 | M12: GB_stNull | O12: 5 | P12: 1 | Q12: 5
A13: 647 | B13: Syphilis treatment | C13: 1 | D13: 4, 6 | E13: 2 | F13: 2 | G13: Follow-up | H13: GB_stNull | I13: 7 | J13: Midwifery professionals | K13: 100 | M13: GB_stNull | O13: 5 | P13: 1 | Q13: 5
A14: 647 | B14: Syphilis treatment | C14: 1 | D14: 4, 6 | E14: 9 | F14: 0 | H14: GB_stNull | I14: 1 | J14: Outpatient visit | K14: 100 | L14: Part of ANC visit | M14: GB_stNull | Q14: 0
A15: 647 | B15: Syphilis treatment | C15: 1 | D15: 4, 6 | E15: 9 | F15: 0 | H15: GB_stNull | I15: 2 | J15: Inpatient day | K15: 100 | M15: GB_stNull | Q15: 0
A17: Removed 10/27/2025
A18: <Intervention Master ID> | B18: <Intervention Name> | C18: <Special Case Type Master IDs> | D18: <Delivery Channel Master IDs> | E18: <Treatment Input Type Master ID> | F18: <Group Master ID> | G18: <Group Name> | H18: <Group String Constant> | I18: <Input Master ID> | J18: <Input Name> | K18: <Percent Receiving or Percent Treated By> | L18: <Note> | M18: <Note String Constant> | N18: <Number of Items> | O18: <Times per Day or Minutes> | P18: <Days per Case or Number of Days> | Q18: <Units per Case or Units per Person>
A19: 549 | B19: PLHIV not on ART ≥ 10 years, without serious illness | D19: 4, 6, 7 | E19: 1 | F19: 1 | G19: W4SS positive followed by CRP, sequential [A.3.5] | H19: GB_stW4SsPosFollowedByCrpSequentialA35 | I19: 1092 | J19: Four symptom screening (W4SS) | K19: 100 | M19: GB_stNull | N19: 1 | O19: 1 | P19: 1 | Q19: 1 | S19: =IF(E19=1, I19, "") -> 1092
A20: 549 | B20: PLHIV not on ART ≥ 10 years, without serious illness | D20: 4, 6, 7 | E20: 1 | F20: 1 | G20: W4SS positive followed by CRP, sequential [A.3.5] | H20: GB_stW4SsPosFollowedByCrpSequentialA35 | I20: 1157 | J20: Screening test - C-reactive protein with a cut-off of > 5 mg/L | K20: 10 | M20: GB_stNull | N20: 1 | O20: 1 | P20: 1 | Q20: 1 | S20: =IF(E20=1, I20, "") -> 1157
A21: 549 | B21: PLHIV not on ART ≥ 10 years, without serious illness | D21: 4, 6, 7 | E21: 1 | F21: 2 | G21: W4SS single screening algorithm [A.3.1] | H21: GB_stW4SsSingleScreenAlgoA31 | I21: 1092 | J21: Four symptom screening (W4SS) | K21: 0 | M21: GB_stNull | N21: 1 | O21: 1 | P21: 1 | Q21: 1 | S21: =IF(E21=1, I21, "") -> 1092
A22: 549 | B22: PLHIV not on ART ≥ 10 years, without serious illness | D22: 4, 6, 7 | E22: 1 | F22: 3 | G22: CRP single screening algorithm: C-reactive protein with a cut-off of > 5 mg/L [A.3.2] | H22: GB_stCrpSingleScreenAlgoCReactiveProteinCutOff5MgLA32 | I22: 1157 | J22: Screening test - C-reactive protein with a cut-off of > 5 mg/L | K22: 0 | M22: GB_stNull | N22: 1 | O22: 1 | P22: 0 | Q22: 0 | S22: =IF(E22=1, I22, "") -> 1157
A23: 549 | B23: PLHIV not on ART ≥ 10 years, without serious illness | D23: 4, 6, 7 | E23: 1 | F23: 4 | G23: CXR single screening algorithm: Chest X-ray [digital (dxr) vs conventional (cxr)] [A.3.3] | H23: GB_stCxrSingleScreenAlgoChestXRayDigitalDxrVsConventionalCxrA33 | I23: 23 | J23: Chest X-ray (conventional) | K23: 0 | M23: GB_stNull | N23: 1 | O23: 1 | P23: 1 | Q23: 1 | S23: =IF(E23=1, I23, "") -> 23
A24: 549 | B24: PLHIV not on ART ≥ 10 years, without serious illness | D24: 4, 6, 7 | E24: 1 | F24: 5 | G24: W4SS and Chest X-Ray, parallel [A.3.7] | H24: GB_stW4SsChestXRayParallelA37 | I24: 1092 | J24: Four symptom screening (W4SS) | K24: 0 | M24: GB_stNull | N24: 1 | O24: 1 | P24: 1 | Q24: 1 | S24: =IF(E24=1, I24, "") -> 1092
A25: 549 | B25: PLHIV not on ART ≥ 10 years, without serious illness | D25: 4, 6, 7 | E25: 1 | F25: 5 | G25: W4SS and Chest X-Ray, parallel [A.3.7] | H25: GB_stW4SsChestXRayParallelA37 | I25: 23 | J25: Chest X-ray (conventional) | K25: 0 | M25: GB_stNull | N25: 1 | O25: 1 | P25: 1 | Q25: 1 | S25: =IF(E25=1, I25, "") -> 23
A26: 549 | B26: PLHIV not on ART ≥ 10 years, without serious illness | D26: 4, 6, 7 | E26: 1 | F26: 5 | G26: W4SS and Chest X-Ray, parallel [A.3.7] | H26: GB_stW4SsChestXRayParallelA37 | I26: 1074 | J26: Computer-aided detection software for automated reading of digital chest radiographs | K26: 0 | M26: GB_stNull | N26: 1 | O26: 1 | P26: 1 | Q26: 1 | S26: =IF(E26=1, I26, "") -> 1074
A27: 549 | B27: PLHIV not on ART ≥ 10 years, without serious illness | D27: 4, 6, 7 | E27: 1 | F27: 6 | G27: W4SS positive followed by Chest X-Ray, sequential [A.3.8] | H27: GB_stW4SsPosFollowedByChestXRaySequentialA38 | I27: 1092 | J27: Four symptom screening (W4SS) | K27: 0 | M27: GB_stNull | N27: 1 | O27: 1 | P27: 1 | Q27: 1 | S27: =IF(E27=1, I27, "") -> 1092
A28: 549 | B28: PLHIV not on ART ≥ 10 years, without serious illness | D28: 4, 6, 7 | E28: 1 | F28: 6 | G28: W4SS positive followed by Chest X-Ray, sequential [A.3.8] | H28: GB_stW4SsPosFollowedByChestXRaySequentialA38 | I28: 23 | J28: Chest X-ray (conventional) | K28: 0 | M28: GB_stNull | N28: 1 | O28: 1 | P28: 1 | Q28: 1 | S28: =IF(E28=1, I28, "") -> 23
A29: 549 | B29: PLHIV not on ART ≥ 10 years, without serious illness | D29: 4, 6, 7 | E29: 1 | F29: 6 | G29: W4SS positive followed by Chest X-Ray, sequential [A.3.8] | H29: GB_stW4SsPosFollowedByChestXRaySequentialA38 | I29: 1074 | J29: Computer-aided detection software for automated reading of digital chest radiographs | K29: 0 | M29: GB_stNull | N29: 1 | O29: 1 | P29: 1 | Q29: 1 | S29: =IF(E29=1, I29, "") -> 1074
A30: 549 | B30: PLHIV not on ART ≥ 10 years, without serious illness | D30: 4, 6, 7 | E30: 1 | F30: 7 | G30: W4SS negative followed by Chest X-Ray, sequential [A.3.9] | H30: GB_stW4SsNegFollowedByChestXRaySequentialA39 | I30: 1092 | J30: Four symptom screening (W4SS) | K30: 0 | M30: GB_stNull | N30: 1 | O30: 1 | P30: 1 | Q30: 1 | S30: =IF(E30=1, I30, "") -> 1092
... A41: 549 | B41: PLHIV not on ART ≥ 10 years, without serious illness | D41: 4, 6, 7 | E41: 1 | F41: 10 | G41: mWRD single screening algorithm for PLHIV [A.3.11] | H41: GB_stMwrdSingleScreenAlgoPlHIVA311 | I41: 1179 | J41: Truenat MTB RIF Dx (mWRD) | K41: 0 | M41: GB_stNull | N41: 1 | O41: 1 | P41: 1 | Q41: 1 | S41: =IF(E41=1, I41, "") -> 1179
A42: 549 | B42: PLHIV not on ART ≥ 10 years, without serious illness | D42: 4, 6, 7 | E42: 2 | F42: 0 | H42: GB_stNull | I42: 29 | J42: Paramedical practitioners | K42: 100 | M42: GB_stNull | O42: 18 | P42: 1 | Q42: 18 | S42: =IF(E42=1, I42, "")
A43: 549 | B43: PLHIV not on ART ≥ 10 years, without serious illness | D43: 4, 6, 7 | E43: 2 | F43: 0 | H43: GB_stNull | I43: 6 | J43: Nursing professionals | K43: 10 | L43: for CRP | M43: GB_stForCrp | O43: 5 | P43: 1 | Q43: 5 | S43: =IF(E43=1, I43, "")
A44: 549 | B44: PLHIV not on ART ≥ 10 years, without serious illness | D44: 4, 6, 7 | E44: 9 | F44: 0 | H44: GB_stNull | I44: 1 | J44: Outpatient visit | K44: 100 | M44: GB_stNull | Q44: 0 | S44: =IF(E44=1, I44, "")
A45: 570 | B45: Pulmonary TB case finding (patient-initiated), HIV-negative, adults 15+ | D45: 4, 6, 7 | E45: 1 | F45: 1 | G45: Any TB symptom screening and Chest X-ray, parallel | H45: GB_stAnyTBSymptomScreenChestXRayParallel | I45: 1188 | J45: Clinical assessment: any TB symptom | K45: 100 | M45: GB_stNull | N45: 1 | O45: 1 | P45: 1 | Q45: 1
A46: 570 | B46: Pulmonary TB case finding (patient-initiated), HIV-negative, adults 15+ | D46: 4, 6, 7 | E46: 1 | F46: 1 | G46: Any TB symptom screening and Chest X-ray, parallel | H46: GB_stAnyTBSymptomScreenChestXRayParallel | I46: 23 | J46: Chest X-ray (conventional) | K46: 100 | M46: GB_stNull | N46: 1 | O46: 1 | P46: 1 | Q46: 1
A47: 570 | B47: Pulmonary TB case finding (patient-initiated), HIV-negative, adults 15+ | D47: 4, 6, 7 | E47: 1 | F47: 1 | G47: Any TB symptom screening and Chest X-ray, parallel | H47: GB_stAnyTBSymptomScreenChestXRayParallel | I47: 1074 | J47: Computer-aided detection software for automated reading of digital chest radiographs | K47: 100 | M47: GB_stNull | N47: 1 | O47: 1 | P47: 1 | Q47: 1
A48: 570 | B48: Pulmonary TB case finding (patient-initiated), HIV-negative, adults 15+ | D48: 4, 6, 7 | E48: 2 | F48: 0 | H48: GB_stNull | I48: 1 | J48: General medical practitioners | K48: 100 | M48: GB_stNull | O48: 4 | P48: 1 | Q48: 4
A49: 570 | B49: Pulmonary TB case finding (patient-initiated), HIV-negative, adults 15+ | D49: 4, 6, 7 | E49: 2 | F49: 0 | H49: GB_stNull | I49: 12 | J49: Medical imaging and therapeutic equipment technicians | K49: 100 | M49: GB_stNull | O49: 5 | P49: 1 | Q49: 5
A50: 570 | B50: Pulmonary TB case finding (patient-initiated), HIV-negative, adults 15+ | D50: 4, 6, 7 | E50: 2 | F50: 0 | H50: GB_stNull | I50: 5 | J50: Medical assistants | K50: 100 | M50: GB_stNull | O50: 8 | P50: 1 | Q50: 8
A51: 570 | B51: Pulmonary TB case finding (patient-initiated), HIV-negative, adults 15+ | D51: 4, 6, 7 | E51: 2 | F51: 0 | H51: GB_stNull | I51: 29 | J51: Paramedical practitioners | K51: 100 | M51: GB_stNull | O51: 18 | P51: 1 | Q51: 18
...

Sheet DrugSupplyDB
A1: <Master ID> | B1: <Constant> | C1: <Name in English> | D1: <String Constant> | E1: <Type> | F1: <Unit Cost> | G1: <Logistics - ColdStorage> | H1: <Logistics - Weight> | I1: <Logistics - Volume> | J1: <Logistics - Family> | K1: <Logistics - UoM_wt> | L1: <Logistics - UoM_cubic> | M1: <Logistics - ForecastError> | N1: <Logistics - Importance> | O1: <Logistics - NonCriticalFraction> | P1: <Logistics - StandardFraction> | Q1: <Logistics - CriticalFraction> | R1: <Logistics - Cost per Pack> | S1: <Logistics - Units per Pack> | T1: <Logistics - Notes> | U1: <Logistics - CostTypeID> | V1: <Source> | W1: <Program Area Filters> | X1: <Comment>
A2: 1 | B2: IC_DS_AlbendazoleTablet400Mg | C2: Albendazole, tablet, 400 mg | D2: GB_stAlbendazoleTablet400Mg | E2: 1 | F2: 0.04 | G2: FALSE | H2: 0.0003 | I2: 1.3227513e-06 | Q2: 1 | R2: 2.19 | S2: 100 | U2: 20 | V2: MSH 2014 | W2: 1, 15, 28 | X2: Updated from .6
A3: 2 | B3: IC_DS_AmoxicillinCaplet250Mg | C3: Amoxicillin, caplet, 250 mg | D3: GB_stAmoxicillinCaplet250Mg | E3: 1 | F3: 0.02 | G3: FALSE | H3: 0.0003 | I3: 1.3227513e-06 | K3: kg | L3: m3 | M3: 25 | N3: Normal | O3: 0.2 | P3: 0.5 | Q3: 0.3 | R3: 15.8 | S3: 1000 | U3: 3 | V3: MSH 2014 | W3: 1, 15, 28 | X3: Updated from .06
A4: 3 | B4: IC_DS_AmoxicillinPowderOralSuspensi | C4: Amoxicillin, powder/oral suspension, 125 mg/5 ml | D4: GB_stAmoxicillinPowderOralSuspension125Mg5Ml | E4: 1 | F4: 0.03 | G4: FALSE | H4: 0.035 | I4: 0.00015432099 | K4: kg | L4: m3 | M4: 25 | N4: Normal | O4: 0.2 | P4: 0.5 | Q4: 0.3 | R4: 0.52 | S4: 20 | U4: 3 | V4: MSH 2014 | W4: 28 | X4: Updated from 0.0818; Median supplier price given as 0.0666/ml so doubled
A5: 4 | B5: IC_DS_AmpicillinPowderForInjection5 | C5: Ampicillin, powder for injection, 500 mg, vial | D5: GB_stAmpicillinPowderInject500MgVial | E5: 1 | F5: 0.13 | G5: FALSE | H5: 0.035 | I5: 0.00015432099 | Q5: 1 | R5: 3.6 | S5: 25 | U5: 3 | V5: MSH 2014 | W5: 1, 15, 28 | X5: Vague
A6: 6 | B6: IC_DS_ArtemetherLumefantrineTablets | C6: Artemether + Lumefantrine, tablets, 20 + 120 mg, 6 x 1 blister | D6: GB_stArtemetherLumefantrineTablets20120Mg6X1Blister | E6: 1 | F6: 0.14 | G6: FALSE | H6: 0.0003 | I6: 1.3227513e-06 | K6: kg | L6: m3 | M6: 25 | N6: Normal | O6: 0.1 | P6: 0.2 | Q6: 0.7 | R6: 0 | S6: 1 | U6: 20 | V6: MSH 2014 | W6: 15, 21, 28 | X6: Updated from .015; Only one supplier price given (GDF)
A7: 8 | B7: IC_DS_ArtesunateAmodiaquineTablets5 | C7: Artesunate + Amodiaquine, tablets, 50 mg + 153 mg, 3 + 3 blister | D7: GB_stArtesunateAmodiaquineTablets50Mg153Mg33Blister | E7: 1 | F7: 0.45 | G7: FALSE | H7: 0.0003 | I7: 1.3227513e-06 | M7: 0 | O7: 0 | P7: 0 | Q7: 1 | R7: 3.03 | S7: 10 | U7: 20 | V7: MSH 2014 | W7: 15, 21 | X7: Could not find
A8: 9 | B8: IC_DS_ArtesunateSpTablets50Mg500Mg2 | C8: Artesunate + SP, tablets, 50 mg + 500 mg + 25 mg, 3 + 1 blister | D8: GB_stArtesunateSpTablets50Mg500Mg25Mg31Blister | E8: 1 | F8: 0.4 | G8: FALSE | H8: 0.0003 | I8: 1.3227513e-06 | M8: 0 | O8: 0 | P8: 0 | Q8: 1 | R8: 5.5 | S8: 10 | U8: 20 | V8: UNICEF Supply Catalogue | W8: 15, 21 | X8: Could not find
A9: 10 | B9: IC_DS_AtenololTablets50Mg | C9: Atenolol, tablets, 50 mg | D9: GB_stAtenololTablets50Mg | E9: 1 | F9: 0.01 | G9: FALSE | H9: 0.0003 | I9: 1.3227513e-06 | Q9: 1 | R9: 5.07 | S9: 1000 | U9: 20 | V9: MSH 2014 | W9: 30 | X9: Updated from .00473
A10: 11 | B10: IC_DS_AtropineSulphateInjection1MgI | C10: Atropine sulphate, injection, 1 mg in 1 ml ampoule | D10: GB_stAtropineSulphateInject1Mg1MlAmpoule | E10: 1 | F10: 0.14 | G10: FALSE | H10: 0.006 | I10: 2.6455026e-05 | M10: 0 | O10: 0 | P10: 0 | Q10: 1 | R10: 1.19 | S10: 10 | U10: 20 | V10: MSH 2014 | W10: 1 | X10: Updated from .00457
A11: 13 | B11: IC_DS_BagUrineCollecting2000Ml | C11: Bag, urine, collecting, 2000 ml | D11: GB_stBagUrineCollecting2000Ml | E11: 2 | F11: 0.36 | G11: FALSE | H11: 0.0011022928 | I11: 4.8601974e-06 | M11: 0 | O11: 0 | P11: 0 | Q11: 1 | R11: 0.31 | S11: 1 | U11: 3 | V11: UNICEF Supply Catalogue | W11: 1 | X11: Vague
A12: 14 | B12: IC_DS_BcgVaccine | C12: BCG vaccine | D12: GB_stBCGImmunization | E12: 1 | F12: 0.1995 | G12: TRUE | H12: 0.035 | I12: 0.00015432099 | K12: kg | L12: m3 | M12: 25 | O12: 0.2 | P12: 0.3 | Q12: 0.5 | R12: 2.12 | S12: 20 | U12: 31 | V12: UNICEF Supply Catalogue | W12: 20
A13: 15 | B13: IC_DS_BenzathineBenzylpenicillinPow | C13: Benzathine benzylpenicillin, powder for injection, 2.4 million IU | D13: GB_stBenzathineBenzylpenicillinPowderInject24MillionIu | E13: 1 | F13: 0.26 | G13: FALSE | H13: 0.035 | I13: 0.00015432099 | N13: Normal | Q13: 1 | R13: 33.79 | S13: 50 | U13: 3 | V13: MSH 2014 | W13: 1, 28 | X13: Vague
A14: 17 | B14: IC_DS_BloodCollectingTube5Ml | C14: Blood collecting tube, 5 ml | D14: GB_stBloodCollectingTube5Ml | E14: 2 | F14: 0.24 | G14: FALSE | H14: 0.0011022928 | I14: 4.8601974e-06 | M14: 0 | O14: 0 | P14: 0 | Q14: 1 | R14: 14.4 | S14: 100 | U14: 20 | W14: 1, 23, 30 | X14: Repeat?
A15: 18 | B15: IC_DS_BloodCulture | C15: Blood culture | D15: GB_stBloodCulture | E15: 2 | F15: 0 | G15: FALSE | H15: 0.0011022928 | I15: 4.8601974e-06 | Q15: 1 | R15: 0 | S15: 1 | U15: 20 | W15: 1
A16: 19 | B16: IC_DS_BloodOneUnit | C16: Blood, one unit | D16: GB_stBloodOneUnit | E16: 2 | F16: 0 | G16: FALSE | H16: 0.0011022928 | I16: 4.8601974e-06 | Q16: 1 | R16: 0 | S16: 1 | U16: 20 | W16: 1, 15 | X16: Updated from .345; Median supplier price is 0.1641/ml therefore doubled
A17: 20 | B17: IC_DS_CalciumTablet600Mg | C17: Calcium, tablet, 600 mg | D17: GB_stCalciumTablet600Mg | E17: 1 | F17: 0.02 | G17: FALSE | H17: 0.0003 | I17: 1.3227513e-06 | M17: 0 | O17: 0 | P17: 0 | Q17: 1 | R17: 0.045 | S17: 1 | U17: 20 | V17: MSH 2014 | W17: 28 | X17: Updatd from .0296
A18: 21 | B18: IC_DS_CeftriaxonePowderForInjection2 | C18: Ceftriaxone, powder for injection, 250 ml vial | D18: GB_stCeftriaxonePowderInject250MlVial | E18: 1 | F18: 0.52 | G18: FALSE | H18: 0.035 | I18: 0.00015432099 | M18: 0 | O18: 0 | P18: 0 | Q18: 1 | R18: 11.85 | S18: 50 | U18: 20 | V18: MSH 2014 | W18: 1, 28
A19: 22 | B19: IC_DS_Cephalotin100MlVial | C19: Cephalotin, 100 ml vial | D19: GB_stCephalotin100MlVial | E19: 1 | F19: 0.84 | G19: FALSE | H19: 0.035 | I19: 0.00015432099 | Q19: 1 | R19: 0.84 | S19: 1 | U19: 3 | W19: 1
A20: 23 | B20: IC_DS_ChestXRay | C20: Chest X-ray | D20: GB_stChestXRay | E20: 2 | F20: 1.7 | G20: FALSE | H20: 0.027 | I20: 0.00011904762 | Q20: 1 | R20: 0 | S20: 1 | U20: 28 | W20: 1, 22 | X20: UNICEF Catalogue has price of 1,556.19 for equipment to be used in outpatient therapeutic feeding centres intended for severely acute malnourished children, 5 Ambulatory Feeding Therapeutic Centres (AFTC) sites, and 500 patients/3 months; separate kit contains registration materials
A21: 26 | B21: IC_DS_CiprofloxacinTablet250Mg | C21: Ciprofloxacin, tablet, 250 mg | D21: GB_stCiprofloxacinTablet250Mg | E21: 1 | F21: 0.02 | G21: FALSE | H21: 0.0003 | I21: 1.3227513e-06 | Q21: 1 | R21: 0.24 | S21: 10 | U21: 20 | V21: MSH 2014 | W21: 1, 15, 28 | X21: vague
A22: 27 | B22: IC_DS_CleanDeliveryKit | C22: Clean delivery kit | D22: GB_stCleanDeliveryKit | E22: 2 | F22: 1.37 | G22: FALSE | H22: 0.0011022928 | I22: 4.8601974e-06 | Q22: 1 | R22: 1.37 | S22: 1 | U22: 20 | W22: 1 | X22: Updated from .2034; price per ml is .3847 so doubled
A23: 29 | B23: IC_DS_CondomFemale | C23: Condom, female | D23: GB_stCondomFemale | E23: 2 | F23: 0.74 | G23: FALSE | H23: 0.0011022928 | I23: 4.8601974e-06 | M23: 0 | O23: 0 | P23: 0 | Q23: 1 | R23: 0.6 | S23: 1 | U23: 5 | V23: MSH 2014 | W23: 1 | X23: Vague: two options: Price is 48.44 for RUTF biscuit,packs,510g./CAR-24; Therapeutic RUTF spread for $54 for sachets of 92g/CAR-150 (which is repeated below in line 382)
A24: 30 | B24: IC_DS_CondomMale | C24: Condom, male | D24: GB_stCondomMale | E24: 2 | F24: 0.03 | G24: FALSE | H24: 0.0011022928 | I24: 4.8601974e-06 | N24: Normal | Q24: 1 | R24: 2.95 | S24: 144 | U24: 5 | V24: MSH 2014 | W24: 1, 23 | X24: Couldn't find
A25: 31 | B25: IC_DS_CottonSwab | C25: Cotton swab | D25: GB_stCottonSwab | E25: 2 | F25: 0.1 | G25: FALSE | H25: 0.0011022928 | I25: 4.8601974e-06 | M25: 0 | O25: 0 | P25: 0 | Q25: 1 | R25: 1.62 | S25: 100 | U25: 3 | V25: UNICEF Supply Catalogue | W25: 1, 15
A26: 32 | B26: IC_DS_DeliveryRecord | C26: Delivery record | D26: GB_stDeliveryRecord | E26: 2 | F26: 0 | G26: FALSE | H26: 0.0011022928 | I26: 4.8601974e-06 | M26: 0 | O26: 0 | P26: 0 | Q26: 1 | R26: 0 | S26: 1 | U26: 20 | W26: 1
A27: 33 | B27: IC_DS_DepotMedroxyprogAceta150 | C27: Depot-Medroxyprogesterone Acetate 150 mg - 3 monthly | D27: GB_stDepotMedroxyprogesteroneAcetate150Mg3Monthly | E27: 1 | F27: 0.75 | G27: FALSE | H27: 0.0011022928 | I27: 4.8601974e-06 | M27: 0 | N27: Normal | O27: 0 | P27: 0 | Q27: 1 | R27: 0.68 | S27: 1 | U27: 5 | V27: MSH 2014 | W27: 1 | X27: Can't find
A28: 36 | B28: IC_DS_Dexamethasone1MlInjection4MgM | C28: Dexamethasone, 1 ml injection, 4 mg/ml | D28: GB_stDexamethasone1MlInject4MgMl | E28: 1 | F28: 0.17 | G28: FALSE | H28: 0.035 | I28: 0.00015432099 | M28: 0 | O28: 0 | P28: 0 | Q28: 1 | R28: 6 | S28: 100 | U28: 20 | V28: MSH 2014 | W28: 1 | X28: Updated from .2286111; Price is 8.96 for box of 36 for curved needle
A29: 37 | B29: IC_DS_DiazepamInjection5MgMlIn2MlAm | C29: Diazepam, injection, 5 mg/ml, in 2 ml ampoule | D29: GB_stDiazepamInject5MgMl2MlAmpoule | E29: 1 | F29: 0.13 | G29: FALSE | H29: 0.006 | I29: 2.6455026e-05 | M29: 0 | O29: 0 | P29: 0 | Q29: 1 | R29: 0.818 | S29: 10 | U29: 20 | V29: MSH 2014 | W29: 1 | X29: Updated from 2.83; Median price given was 0.0044/ml so multiplied times 1000
A30: 40 | B30: IC_DS_DtpVaccine | C30: DTP vaccine | D30: GB_stDtpVaccine | E30: 1 | F30: 0.2888 | G30: TRUE | H30: 0.035 | I30: 0.00015432099 | Q30: 1 | R30: 2.82 | S30: 20 | U30: 20 | V30: MSH 2014 | W30: 20 | X30: Vague
A31: 43 | B31: IC_DS_ErythromycinTablet250Mg | C31: Erythromycin, tablet, 250 mg | D31: GB_stErythromycinTablet250Mg | E31: 1 | F31: 0.04 | G31: FALSE | H31: 0.0003 | I31: 1.3227513e-06 | M31: 0 | N31: Normal | O31: 0 | P31: 0 | Q31: 1 | R31: 4.26 | S31: 100 | U31: 20 | V31: MSH 2014 | W31: 1 | X31: Updated from .0729;this is median unit cost and doesn't say anything about blister sheet
A32: 50 | B32: IC_DS_FerrousSaltFolicAcidTablet200 | C32: Ferrous Salt + Folic Acid, tablet, 200 + 0.25 mg | D32: GB_stFerrousSaltFolicAcidTablet200025Mg | E32: 1 | F32: 0.0027 | G32: FALSE | H32: 0.0003 | I32: 1.3227513e-06 | Q32: 1 | R32: 1.4 | S32: 1000 | U32: 20 | V32: MSH 2014 | W32: 1 | X32: WHO GPRM has median unit price of 1.537 for strengths of 4g, 100g 60% w/w
A33: 51 | B33: IC_DS_FoleyCatheter | C33: Foley catheter | D33: GB_stFoleyCatheter | E33: 2 | F33: 0.58 | G33: FALSE | H33: 0.0011022928 | I33: 4.8601974e-06 | K33: kg | L33: m3 | M33: 25 | O33: 0.2 | P33: 0.5 | Q33: 0.3 | R33: 0.51 | S33: 1 | U33: 7 | V33: UNICEF Supply Catalogue | W33: 1 | X33: WHO gives cost per year is 646.48
A34: 52 | B34: IC_DS_FolicAcidTablet5Mg | C34: Folic acid, tablet, 5 mg | D34: GB_stFolicAcidTablet5Mg | E34: 1 | F34: 0.0032 | G34: FALSE | H34: 0.0003 | I34: 1.3227513e-06 | Q34: 1 | R34: 4.73 | S34: 1000 | U34: 20 | V34: MSH 2014 | W34: 1, 28 | X34: Updated from .044
A35: 53 | B35: IC_DS_FurosemideTablets40Mg | C35: Furosemide, tablets, 40 mg | D35: GB_stFurosemideTablets40Mg | E35: 1 | F35: 0.01 | G35: FALSE | H35: 0.0003 | I35: 1.3227513e-06 | Q35: 1 | R35: 4.57 | S35: 1000 | U35: 20 | V35: MSH 2014 | X35: Updated from .31
A36: 55 | B36: IC_DS_GauzePad10X10CmSterile | C36: Gauze pad, 10 x 10 cm, sterile | D36: GB_stGauzePad10X10CmSterile | E36: 2 | F36: 0.05 | G36: FALSE | H36: 0.003 | I36: 1.3227513e-05 | N36: Normal | Q36: 1 | R36: 0.19 | S36: 5 | U36: 7 | V36: UNICEF Supply Catalogue | W36: 1, 23 | X36: Updated from .82; only one supplier and no buyer prices available
A37: 56 | B37: IC_DS_GentamicinInj10MgMl2MlAmp | C37: Gentamicin inj 10 mg/ml 2 ml amp | D37: GB_stGentamicinInj10MgMl2MlAmp | E37: 1 | F37: 0.19 | G37: FALSE | H37: 0.006 | I37: 2.6455026e-05 | M37: 0 | N37: Normal | O37: 0 | P37: 0 | Q37: 1 | R37: 12.47 | S37: 100 | U37: 20 | V37: MSH 2014 | W37: 15 | X37: Repeat
A38: 57 | B38: IC_DS_GentamycinInjection40MgMlIn2M | C38: Gentamycin, injection, 40 mg/ml in 2 ml vial | D38: GB_stGentamycinInject40MgMl2MlVial | E38: 1 | F38: 0.18 | G38: FALSE | H38: 0.035 | I38: 0.00015432099 | K38: kg | L38: m3 | M38: 25 | O38: 0.1 | P38: 0.2 | Q38: 0.7 | R38: 0 | S38: 1 | U38: 20 | V38: MSH 2014 | W38: 1, 28 | X38: Updated from .033
A39: 58 | B39: IC_DS_GlovesExamLatexDisposablePair | C39: Gloves, exam, latex, disposable, pair | D39: GB_stGlovesExamLatexDisposablePair | E39: 2 | F39: 0.06 | G39: FALSE | H39: 0.05 | I39: 0.00022045855 | Q39: 1 | R39: 5.49 | S39: 100 | U39: 7 | V39: UNICEF Supply Catalogue | W39: 1, 23, 30 | X39: Vague/couldn't find; MSH has a variety of HIV 1+2 tests but not Doublechck
A40: 59 | B40: IC_DS_GlovesSurgeon’SLatexDisposabl | C40: Gloves, surgeon’s, latex, disposable, sterile, pair | D40: GB_stGlovesSurgeon’SLatexDisposableSterilePair | E40: 2 | F40: 0.19 | G40: FALSE | H40: 0.05 | I40: 0.00022045855 | Q40: 1 | R40: 0.22 | S40: 1 | U40: 3 | V40: UNICEF Supply Catalogue | W40: 1, 23 | X40: Repeat of line 415
...

Sheet Removed Drugs and Supplies
A1: <Master ID> | B1: <Constant> | C1: <Name in English> | D1: <String Constant> | E1: <Type> | F1: <Unit Cost> | G1: <Logistics - Family> | H1: <Logistics - Weight (kg)> | I1: <Logistics - UoM_wt> | J1: <Logistics - Cubic Ft (m)> | K1: <Logistics - UoM_cubic> | L1: <Logistics - ForecastError> | M1: <Logistics - Importance> | N1: <Logistics - NonCriticalFraction> | O1: <Logistics - StandardFraction> | P1: <Logistics - CriticalFraction> | Q1: <Logistics - Cost per Pack> | R1: <Logistics - Units per Pack> | S1: <Logistics - Notes> | T1: <Logistics - CostTypeID> | U1: <Source> | V1: <Program Area Filters> | W1: <Comment>
A2: 681 | B2: IC_DS_ElectrolyteWasting | C2: Electrolyte wasting | D2: GB_stElectrolyteWasting | E2: 2 | F2: 14.5152 | Q2: 14.5152 | R2: 1 | U2: WHO update for OHT_drugs and supplies_11 dec 2015 | V2: 22
A3: 5 | B3: IC_DS_AntenatalCareRecord | C3: Antenatal care record | D3: GB_stAntenatalCareRecord | E3: 2 | F3: 0 | J3: 0 | L3: 0 | N3: 0 | O3: 0 | P3: 1 | Q3: 0 | R3: 1 | T3: 20 | W3: Updated from .013;
A4: 7 | B4: IC_DS_Artemether20MgMlInjection1Ml | C4: Artemether 20 mg/ml injection/1 ml | D4: GB_stArtemether20MgMlInject1Ml | E4: 1 | F4: 0.66 | H4: 0.44 | J4: 0.0025 | L4: 0 | N4: 0 | O4: 0 | P4: 1 | Q4: 0.68 | R4: 1 | T4: 20 | U4: MSH 2014 | W4: Could not find
A5: 12 | B5: IC_DS_BacteriuriaTest | C5: Bacteriuria test | D5: GB_stBacteriuriaTest | E5: 2 | F5: 0.12 | J5: 0 | P5: 1 | Q5: 0.12 | R5: 1 | T5: 20 | W5: No change
A6: 16 | B6: IC_DS_Betamethasone12MgInjection | C6: Betamethasone, 12 mg injection | D6: GB_stBetamethasone12MgInject | E6: 1 | F6: 2.18 | J6: 0 | L6: 0 | N6: 0 | O6: 0 | P6: 1 | Q6: 14.4 | R6: 1 | T6: 20 | U6: MSH 2014 | W6: Updated from .2185; Did not have 'T-380A' in listing
A7: 24 | B7: IC_DS_ChloramphenicolPowderInj1GVia | C7: Chloramphenicol, powder/inj, 1 g vial | D7: GB_stChloramphenicolPowderInj1GVial | E7: 1 | F7: 0.5 | H7: 1.06 | J7: 0.002 | L7: 0 | N7: 0 | O7: 0 | P7: 1 | Q7: 6.5 | R7: 5 | T7: 3 | U7: MSH 2014 | W7: Vague; catalogue has the following ORS sachets available: 100 sachets of 20.5g of Low Osmolarity sachet for 1000 ml (1.0 Litre) for 6.48; 1000 of the same for 68.36; 100 of the same with orange flavor for 9.46; 1000 of these orange flavored sachets for 98.12; 1000 sachets of 10.2 gram low osmolarity ORS is 60.55; 1000 of these but orange flavored 10.2 sachets for 75.30
A8: 25 | B8: IC_DS_ChloramphenicolOralSuspension | C8: Chloramphenicol, oral suspension 125 mg/5 ml, 60 ml bottle | D8: GB_stChloramphenicolOralSuspension125Mg5Ml60MlBottle | E8: 1 | F8: 0.58 | H8: 0.13 | J8: 0.0003 | L8: 0 | N8: 0 | O8: 0 | P8: 1 | Q8: 0.68 | R8: 1 | T8: 3 | U8: MSH 2014 | W8: Vague
A9: 28 | B9: IC_DS_ClindamycinTabcap300Mg | C9: Clindamycin, tabcap, 300 mg | D9: GB_stClindamycinTabcap300Mg | E9: 1 | F9: 0.1 | H9: 0.44 | J9: 0.0016 | P9: 1 | Q9: 7.5 | R9: 30 | T9: 20 | U9: MSH 2014 | W9: updated from 3.5; only buyer price available
A10: 34 | B10: IC_DS_DepotMedroxyprogAceta25 | C10: Depot-Medroxyprogesterone Acetate 25 mg + estradiol cypionate 5 mg - 1 monthly | D10: GB_stDepotMedroxyprogesteroneAcetate25MgEstradiolCypionate5Mg1Monthly | E10: 1 | F10: 0 | J10: 0 | P10: 1 | Q10: 0 | R10: 1 | T10: 5 | W10: Updated from .5066667; 15.91 price is for braied DEC3 (2/0), 1/2 circle, 30mm round point box of 36; Also available for 23.84 is box of 36 for 26.84
A11: 35 | B11: IC_DS_Desogestrel015MgEthinylEstrad | C11: Desogestrel 0.15 mg + Ethinyl estradiol 30 mcg, cycle | D11: GB_stDesogestrel015MgEthinylEstradiol30McgCycle | E11: 1 | F11: 0.72 | J11: 0 | L11: 0 | N11: 0 | O11: 0 | P11: 1 | Q11: 0 | R11: 1 | T11: 5 | U11: MSH 2014 | W11: Can't find
A12: 38 | B12: IC_DS_DietarySupplementsCountrySpec | C12: Dietary supplements (country-specific) | D12: GB_stDietarySupplementsCountrySpecific | E12: 1 | F12: 0 | J12: 0 | L12: 0 | N12: 0 | O12: 0 | P12: 1 | Q12: 0 | R12: 1 | T12: 23 | W12: Vague; UNICEF catalogue has Starter kit for Haemoglobin colour scale for 28.40
A13: 39 | B13: IC_DS_DigoxinTabcap250Mcg | C13: Digoxin, tabcap, 250 mcg | D13: GB_stDigoxinTabcap250Mcg | E13: 1 | F13: 0.01 | H13: 0.19 | J13: 0.0005 | L13: 0 | N13: 0 | O13: 0 | P13: 1 | Q13: 0.364 | R13: 28 | T13: 20 | U13: MSH 2014 | W13: Updated from .085; Price is 1.22 for a vial of 20 doses; vial of 10 doses also available for 1.00
A14: 41 | B14: IC_DS_DrugKitForCSectionAndComplexD | C14: Drug kit for C-section and complex deliveries | D14: GB_stDrugKitCSectionComplexDeliveries | E14: 2 | F14: 2009.11 | J14: 0 | P14: 1 | Q14: 2009.11 | R14: 1 | T14: 20 | W14: Updated from 0
A15: 42 | B15: IC_DS_ErgometrineTablet02Mg | C15: Ergometrine, tablet, 0.2 mg | D15: GB_stErgometrineTablet02Mg | E15: 1 | F15: 0.01 | H15: 0.37 | J15: 0.0012 | P15: 1 | Q15: 17.5 | R15: 1000 | T15: 20 | U15: MSH 2014
A16: 44 | B16: IC_DS_EthambutolTabCap100Mg | C16: Ethambutol, tab-cap, 100 mg | D16: GB_stEthambutolTabCap100Mg | E16: 1 | F16: 0.04 | H16: 0.22 | J16: 0.0007 | L16: 0 | N16: 0 | O16: 0 | P16: 1 | Q16: 15 | R16: 1000 | T16: 1 | U16: MSH 2014 | W16: Repeat of 315 except for jar
A17: 45 | B17: IC_DS_EthambutolTabCap400Mg | C17: Ethambutol, tab-cap, 400 mg | D17: GB_stEthambutolTabCap400Mg | E17: 1 | F17: 0.03 | H17: 0.22 | J17: 0.0007 | L17: 0 | N17: 0 | O17: 0 | P17: 1 | Q17: 39.9 | R17: 1000 | T17: 1 | U17: MSH 2014 | W17: Updated from .0213; Only one supplier price (GDF) and no buyer prices
A18: 46 | B18: IC_DS_F100TherapeuticDietSachet456G | C18: F-100 therapeutic diet, sachet, 456 g for 2.4 liters liquid diet | D18: GB_stF100TherapeuticDietSachet456G24LitersLiquidDiet | E18: 2 | F18: 0.64 | J18: 0 | P18: 1 | Q18: 57.6 | R18: 90 | T18: 23 | W18: Updated from 0; Only one supply price available
A19: 47 | B19: IC_DS_F100TherapeuticMilkSachet456G | C19: F-100 therapeutic milk,sachet, 456 g | D19: GB_stF100TherapeuticMilkSachet456G | E19: 2 | F19: 1.98 | J19: 0 | P19: 1 | Q19: 59.4 | R19: 30 | T19: 23 | W19: Updated from .5648
A20: 48 | B20: IC_DS_F75TherapeuticDietSachet410GF | C20: F-75 therapeutic diet, sachet, 410 g for 2.4 liters liquid diet | D20: GB_stF75TherapeuticDietSachet410G24LitersLiquidDiet | E20: 2 | F20: 0.48 | J20: 0 | L20: 0 | N20: 0 | O20: 0 | P20: 1 | Q20: 57.9 | R20: 120 | T20: 23 | W20: Updated from 0; Only one supplier price given; Median buyer price is: 1.6423
A21: 49 | B21: IC_DS_F75TherapeuticMilkSachet410G | C21: F-75 therapeutic milk, sachet, 410 g | D21: GB_stF75TherapeuticMilkSachet410G | E21: 2 | F21: 1.55 | J21: 0 | P21: 1 | Q21: 31.01 | R21: 20 | T21: 23 | W21: Updated from .2219; only one supplier price available (GDF)
A22: 54 | B22: IC_DS_GauzePad10X10CmNonSterile | C22: Gauze pad, 10 x 10 cm, non-sterile | D22: GB_stGauzePad10X10CmNonSterile | E22: 2 | F22: 0.03 | H22: 0.33 | J22: 0.002 | L22: 0 | N22: 0 | O22: 0 | P22: 1 | Q22: 3.21 | R22: 100 | T22: 7 | U22: UNICEF Supply Catalogue
A23: 64 | B23: IC_DS_ImplantSingleRod68MgEtonogest | C23: Implant, single rod - 68 mg etonogestrel | D23: GB_stImplantSingleRod68MgEtonogestrel | E23: 2 | F23: 11.11 | I23: kg | J23: 0 | K23: m3 | L23: 25 | M23: Normal | N23: 0.1 | O23: 0.2 | P23: 0.7 | Q23: 14 | R23: 1 | T23: 5 | U23: MHS 2014 | W23: Vague
A24: 65 | B24: IC_DS_ImplantSixRod36MgLevonorgestr | C24: Implant, six rod - 36 mg levonorgestrel per rod | D24: GB_stImplantSixRod36MgLevonorgestrelPerRod | E24: 2 | F24: 23 | J24: 0 | P24: 1 | Q24: 23 | R24: 1 | T24: 5 | W24: UNICEF catalogue has diarrhea treatment kit for 4,107.97
A25: 67 | B25: IC_DS_InjectionSuppliesCottonTapeEt | C25: Injection supplies (cotton, tape, etc) | D25: GB_stInjectSuppCottonTapeEtc | E25: 2 | F25: 0.05 | J25: 0 | P25: 1 | Q25: 0.05 | R25: 1 | W25: Vague
A26: 70 | B26: IC_DS_IudMultiload375StandardSl | C26: IUD, Multiload 375 Standard/SL | D26: GB_stIudMultiload375StandardSl | E26: 2 | F26: 1.39 | H26: 0.3 | J26: 0.0063 | L26: 0 | N26: 0 | O26: 0 | P26: 1 | Q26: 69.56 | R26: 50 | T26: 5 | W26: Vague
A27: 73 | B27: IC_DS_Levonorgestrel003MgCycleOf28P | C27: Levonorgestrel 0.03 mg, cycle of 28 pills | D27: GB_stLevonorgestrel003MgCycle28Pills | E27: 1 | F27: 0.44 | H27: 0.03 | J27: 0.0002 | L27: 0 | N27: 0 | O27: 0 | P27: 1 | Q27: 0.28 | R27: 1 | T27: 5 | U27: MSH 2014 | W27: Updated from .14
A28: 75 | B28: IC_DS_Levonorgestrel00500750125MgEt | C28: Levonorgestrel 0.05/0.075/0.125 mg +Ethinyl estradiol 30/40/30 mcg, cycle | D28: GB_stLevonorgestrel00500750125MgEthinylEstradiol304030McgCycle | E28: 1 | F28: 0.21 | J28: 0 | P28: 1 | Q28: 0.21 | R28: 1 | T28: 5 | W28: Vague
A29: 77 | B29: IC_DS_Levonorgestrel01502MgEthinylE | C29: Levonorgestrel 0.15/0.2 mg + Ethinyl estradiol 30/40 mcg, cycle | D29: GB_stLevonorgestrel01502MgEthinylEstradiol3040McgCycle | E29: 1 | F29: 0 | J29: 0 | P29: 1 | Q29: 0 | R29: 1 | T29: 5 | W29: Updated from 1.1008; Price given is 0.1171/ml so multiplied by 10
A30: 81 | B30: IC_DS_Lynestrenol05MgCycle | C30: Lynestrenol 0.5 mg, cycle | D30: GB_stLynestrenol05MgCycle | E30: 1 | F30: 0.43 | J30: 0 | P30: 1 | Q30: 1.1219 | R30: 1 | T30: 20 | U30: MSH 2014
A31: 85 | B31: IC_DS_MebendazoleChewableTablet100M | C31: Mebendazole, chewable tablet, 100 mg | D31: GB_stMebendazoleChewableTablet100Mg | E31: 1 | F31: 0.01 | H31: 0.25 | J31: 0.0007 | P31: 1 | Q31: 126 | R31: 100 | T31: 20 | U31: MSH 2014 | W31: Updated from .19
A32: 87 | B32: IC_DS_MetforminTablet500Mg | C32: Metformin, tablet, 500 mg | D32: GB_stMetforminTablet500Mg | E32: 1 | F32: 0.02 | H32: 0.64 | J32: 0.0019 | L32: 0 | N32: 0 | O32: 0 | P32: 1 | Q32: 4.3 | R32: 500 | T32: 20 | U32: MSH 2014 | W32: No price change; Only buyer prices available
A33: 92 | B33: IC_DS_Microscopy | C33: Microscopy | D33: GB_stMicroscopy | E33: 2 | F33: 0 | J33: 0 | L33: 0 | N33: 0 | O33: 0 | P33: 1 | Q33: 0 | R33: 1 | T33: 6 | W33: Updated from .53; Price given is 0.1156/ml so multiplied by 5
A34: 94 | B34: IC_DS_MucusExtractor | C34: Mucus extractor | D34: GB_stMucusExtractor | E34: 2 | F34: 1.64 | H34: 0.04 | J34: 0.0005 | P34: 1 | Q34: 0.96 | R34: 1 | T34: 7 | U34: UNICEF Supply Catalogue | W34: Updated from .147; price for a 10x10cm,ster/BOX-10 is 1.45 therefore divided by 10
A35: 98 | B35: IC_DS_NitriteTest | C35: Nitrite test | D35: GB_stNitriteTest | E35: 2 | F35: 0 | J35: 0 | P35: 1 | Q35: 0 | R35: 1 | T35: 7 | W35: MSH 2014 has one buyer price for a 40mg tablet for 0.0157 and one supplier price for a 50mg tablet for 0.0062
A36: 99 | B36: IC_DS_Norethisterone035MgMicronorCy | C36: Norethisterone 0.35 mg (Micronor), cycle | D36: GB_stNorethisterone035MgMicronorCycle | E36: 1 | F36: 0.5 | J36: 0 | P36: 1 | Q36: 0.5 | R36: 1 | T36: 5 | W36: Updated from .007; Used ferrous salt 20mg/ml suspension/oral preparation; only one supplier price available
A37: 100 | B37: IC_DS_NorethisteroneEnanthate200Mg2 | C37: Norethisterone enanthate 200 mg - 2 monthly | D37: GB_stNorethisteroneEnanthate200Mg2Monthly | E37: 1 | F37: 1.16 | J37: 0 | P37: 1 | Q37: 1.16 | R37: 1 | T37: 5 | W37: Updated from .011; Only one supplier and no buyer price available
A38: 101 | B38: IC_DS_NorethisteroneEnanthate200Mg5 | C38: Norethisterone enanthate 200 mg + 5 mg estradiol valerate - 1 monthly | D38: GB_stNorethisteroneEnanthate200Mg5MgEstradiolValerate1Monthly | E38: 1 | F38: 0.85 | J38: 0 | P38: 1 | Q38: 0.85 | R38: 1 | T38: 5 | W38: No change; Price given is for 1500 capsules of 200mg tablets at 345.69 USD so divided
A39: 102 | B39: IC_DS_Norgestrel030McgEthinylEstrad | C39: Norgestrel 0.30 mcg + Ethinyl estradiol 30 mcg (Lofemenal), cycle | D39: GB_stNorgestrel030McgEthinylEstradiol30McgLofemenalCycle | E39: 1 | F39: 0.25 | I39: kg | J39: 0 | K39: m3 | L39: 25 | N39: 0.2 | O39: 0.3 | P39: 0.5 | Q39: 24.88 | R39: 100 | T39: 5 | W39: No change; price given is $54 for a carton of 150 sachets
A40: 103 | B40: IC_DS_NutritionKitForTherapeuticFee | C40: Nutrition Kit for therapeutic feeding, clinic based | D40: GB_stNutritionKitTherapeuticFeedingClinicBased | E40: 2 | F40: 18.67 | J40: 0 | L40: 0 | N40: 0 | O40: 0 | P40: 1 | Q40: 1866.63 | R40: 100 | T40: 23 | W40: updated from 3.3; Used suspension form; only one buyer price available and no supplier price
...

Sheet PIN_DB
